package test.exceptions

class ExceptionTest():

    let test() : void:
        try:

        catch:

        finally: