package test.exceptions

class ExceptionTest():

    def test() <- void:
        try:

        catch:

        finally: